<robot
  name="drchubo-v3">
  <link
    name="Body_Torso">
    <inertial>
      <origin
        xyz="-0.00653576137697377 2.64726276972488E-05 -0.0481158946001494"
        rpy="0 0 0" />
      <mass
        value="12.0205278528191" />
      <inertia
        ixx="0.139304186384989"
        ixy="3.94986545913099E-06"
        ixz="-0.00823717402834546"
        iyy="0.1033490480381"
        iyz="-5.51332752868618E-06"
        izz="0.138503173370822" />
    </inertial>
    <visual>
      <origin
        xyz="0 0 0"
        rpy="0 0 0" />
      <geometry>
        <mesh
          filename="package://drchubo-v3/meshes/convhull_Torso_merged.stl" />
      </geometry>
      <material
        name="">
        <color
          rgba="0.752941176470588 0.752941176470588 0.752941176470588 1" />
      </material>
    </visual>
    <collision>
      <origin
        xyz="0 0 0"
        rpy="0 0 0" />
      <geometry>
        <mesh
          filename="package://drchubo-v3/meshes/convhull_Torso_merged.stl" />
      </geometry>
    </collision>
  </link>
  <link
    name="Body_TSY">
    <inertial>
      <origin
        xyz="-0.0172313454531017 7.74734146969771E-06 -0.0326399406620081"
        rpy="0 0 0" />
      <mass
        value="4.83018847366242" />
      <inertia
        ixx="0.0242710547439344"
        ixy="4.03308627245632E-06"
        ixz="0.000107562017398343"
        iyy="0.0103772739034659"
        iyz="1.38922193140533E-06"
        izz="0.0286360929381604" />
    </inertial>
    <visual>
      <origin
        xyz="0 0 0"
        rpy="0 0 0" />
      <geometry>
        <mesh
          filename="package://drchubo-v3/meshes/convhull_TSY_merged.stl" />
      </geometry>
      <material
        name="">
        <color
          rgba="0.752941176470588 0.752941176470588 0.752941176470588 1" />
      </material>
    </visual>
    <collision>
      <origin
        xyz="0 0 0"
        rpy="0 0 0" />
      <geometry>
        <mesh
          filename="package://drchubo-v3/meshes/convhull_TSY_merged.stl" />
      </geometry>
    </collision>
  </link>
  <joint
    name="TSY"
    type="revolute">
    <origin
      xyz="-0.00099991 0 -0.2061"
      rpy="0 0 0" />
    <parent
      link="Body_Torso" />
    <child
      link="Body_TSY" />
    <axis
      xyz="0 0 1" />
    <limit
      lower="0"
      upper="0"
      effort="0"
      velocity="0" />
  </joint>
  <link
    name="Body_RHY">
    <inertial>
      <origin
        xyz="0.0357455188333078 -9.87014023896837E-06 -0.0612768789732468"
        rpy="0 0 0" />
      <mass
        value="1.39676631505367" />
      <inertia
        ixx="0.00288796936082902"
        ixy="9.31467192308025E-07"
        ixz="-0.00107856005838791"
        iyy="0.00475787075043952"
        iyz="-1.27885368145267E-06"
        izz="0.00300625958560243" />
    </inertial>
    <visual>
      <origin
        xyz="0 0 0"
        rpy="0 0 0" />
      <geometry>
        <mesh
          filename="package://drchubo-v3/meshes/convhull_RHY_merged.stl" />
      </geometry>
      <material
        name="">
        <color
          rgba="0.752941176470588 0.752941176470588 0.752941176470588 1" />
      </material>
    </visual>
    <collision>
      <origin
        xyz="0 0 0"
        rpy="0 0 0" />
      <geometry>
        <mesh
          filename="package://drchubo-v3/meshes/convhull_RHY_merged.stl" />
      </geometry>
    </collision>
  </link>
  <joint
    name="RHY"
    type="revolute">
    <origin
      xyz="0 -0.0885 -0.0751"
      rpy="0 0 0" />
    <parent
      link="Body_TSY" />
    <child
      link="Body_RHY" />
    <axis
      xyz="0 0 1" />
    <limit
      lower="0"
      upper="0"
      effort="0"
      velocity="0" />
  </joint>
  <link
    name="Body_RHR">
    <inertial>
      <origin
        xyz="-0.0546751887964423 0.000755923439320891 -0.0250478918091924"
        rpy="0 0 0" />
      <mass
        value="1.87327014692152" />
      <inertia
        ixx="0.00271708242471016"
        ixy="6.95355289452482E-06"
        ixz="-0.000124506400404964"
        iyy="0.00314352531523686"
        iyz="-0.000179044888416252"
        izz="0.00241624814316969" />
    </inertial>
    <visual>
      <origin
        xyz="0 0 0"
        rpy="0 0 0" />
      <geometry>
        <mesh
          filename="package://drchubo-v3/meshes/convhull_RHR_merged.stl" />
      </geometry>
      <material
        name="">
        <color
          rgba="0.752941176470588 0.752941176470588 0.752941176470588 1" />
      </material>
    </visual>
    <collision>
      <origin
        xyz="0 0 0"
        rpy="0 0 0" />
      <geometry>
        <mesh
          filename="package://drchubo-v3/meshes/convhull_RHR_merged.stl" />
      </geometry>
    </collision>
  </link>
  <joint
    name="RHR"
    type="revolute">
    <origin
      xyz="0.0520 0 -0.0910"
      rpy="0 0 0" />
    <parent
      link="Body_RHY" />
    <child
      link="Body_RHR" />
    <axis
      xyz="1 0 0" />
    <limit
      lower="0"
      upper="0"
      effort="0"
      velocity="0" />
  </joint>
  <link
    name="Body_RHP">
    <inertial>
      <origin
        xyz="0.014307872736041 0.0329553894436889 -0.191508079337336"
        rpy="0 0 0" />
      <mass
        value="4.08210586510791" />
      <inertia
        ixx="0.0731344926008634"
        ixy="0.00077452257482256"
        ixz="-0.00133507444320974"
        iyy="0.0704116135206437"
        iyz="-0.00380081725669915"
        izz="0.010435218639693" />
    </inertial>
    <visual>
      <origin
        xyz="0 0 0"
        rpy="0 0 0" />
      <geometry>
        <mesh
          filename="package://drchubo-v3/meshes/convhull_RHP_merged.stl" />
      </geometry>
      <material
        name="">
        <color
          rgba="0.752941176470588 0.752941176470588 0.752941176470588 1" />
      </material>
    </visual>
    <collision>
      <origin
        xyz="0 0 0"
        rpy="0 0 0" />
      <geometry>
        <mesh
          filename="package://drchubo-v3/meshes/convhull_RHP_merged.stl" />
      </geometry>
    </collision>
  </link>
  <joint
    name="RHP"
    type="revolute">
    <origin
      xyz="-0.052 -0.0445 0"
      rpy="0 0 0" />
    <parent
      link="Body_RHR" />
    <child
      link="Body_RHP" />
    <axis
      xyz="0 1 0" />
    <limit
      lower="0"
      upper="0"
      effort="0"
      velocity="0" />
  </joint>
  <link
    name="Body_RKP">
    <inertial>
      <origin
        xyz="0.015377 0.023243 -0.16683"
        rpy="0 0 0" />
      <mass
        value="1.5575" />
      <inertia
        ixx="0.023902"
        ixy="-0.00016341"
        ixz="0.0003317"
        iyy="0.021931"
        iyz="-0.00047965"
        izz="0.0043485" />
    </inertial>
    <visual>
      <origin
        xyz="0 0 0"
        rpy="0 0 0" />
      <geometry>
        <mesh
          filename="package://drchubo-v3/meshes/convhull_RKP_merged.stl" />
      </geometry>
      <material
        name="">
        <color
          rgba="0.75294 0.75294 0.75294 1" />
      </material>
    </visual>
    <collision>
      <origin
        xyz="0 0 0"
        rpy="0 0 0" />
      <geometry>
        <mesh
          filename="package://drchubo-v3/meshes/convhull_RKP_merged.stl" />
      </geometry>
    </collision>
  </link>
  <joint
    name="RKP"
    type="revolute">
    <origin
      xyz="0 0.0285 -0.33"
      rpy="0 0 0" />
    <parent
      link="Body_RHP" />
    <child
      link="Body_RKP" />
    <axis
      xyz="0 1 0" />
    <limit
      lower="0"
      upper="0"
      effort="0"
      velocity="0" />
  </joint>
  <link
    name="Body_RAP">
    <inertial>
      <origin
        xyz="0.0155171396909817 0.0515086693793291 0.00905289185767222"
        rpy="0 0 0" />
      <mass
        value="2.28752729357667" />
      <inertia
        ixx="0.00372279383770575"
        ixy="0.000408405026298127"
        ixz="-0.000324861356780796"
        iyy="0.00395779600552089"
        iyz="0.000345535189408416"
        izz="0.00437930917038205" />
    </inertial>
    <visual>
      <origin
        xyz="0 0 0"
        rpy="0 0 0" />
      <geometry>
        <mesh
          filename="package://drchubo-v3/meshes/convhull_RAP_merged.stl" />
      </geometry>
      <material
        name="">
        <color
          rgba="0.752941176470588 0.752941176470588 0.752941176470588 1" />
      </material>
    </visual>
    <collision>
      <origin
        xyz="0 0 0"
        rpy="0 0 0" />
      <geometry>
        <mesh
          filename="package://drchubo-v3/meshes/convhull_RAP_merged.stl" />
      </geometry>
    </collision>
  </link>
  <joint
    name="RAP"
    type="revolute">
    <origin
      xyz="0 -0.0470 -0.3300"
      rpy="0 0 0" />
    <parent
      link="Body_RKP" />
    <child
      link="Body_RAP" />
    <axis
      xyz="0 1 0" />
    <limit
      lower="0"
      upper="0"
      effort="0"
      velocity="0" />
  </joint>
  <link
    name="Body_RAR">
    <inertial>
      <origin
        xyz="-0.053052 -0.0019082 -0.093274"
        rpy="0 0 0" />
      <mass
        value="1.173" />
      <inertia
        ixx="0.0040657"
        ixy="-3.062E-05"
        ixz="-0.0002436"
        iyy="0.0066321"
        iyz="0.00010311"
        izz="0.00448" />
    </inertial>
    <visual>
      <origin
        xyz="0 0 0"
        rpy="0 0 0" />
      <geometry>
        <mesh
          filename="package://drchubo-v3/meshes/convhull_RAR_merged.stl" />
      </geometry>
      <material
        name="">
        <color
          rgba="0.75294 0.75294 0.75294 1" />
      </material>
    </visual>
    <collision>
      <origin
        xyz="0 0 0"
        rpy="0 0 0" />
      <geometry>
        <mesh
          filename="package://drchubo-v3/meshes/convhull_RAR_merged.stl" />
      </geometry>
    </collision>
  </link>
  <joint
    name="RAR"
    type="revolute">
    <origin
      xyz="0.0705 0.063 0"
      rpy="0 0 0" />
    <parent
      link="Body_RAP" />
    <child
      link="Body_RAR" />
    <axis
      xyz="1 0 0" />
    <limit
      lower="0"
      upper="0"
      effort="0"
      velocity="0" />
  </joint>

  <link name="rightFoot">
      <inertial>
          <origin rpy="-0 0 -0" xyz="0 -0 0" />
          <mass value=".1" />
          <inertia ixx="0.0001" ixy="0" ixz="0" iyy="0.0001" iyz="0" izz="0.0001" />
      </inertial>
  </link>

  <joint name="RAR_dummy" type="fixed">
      <origin rpy="0 0 0" xyz="0 0 -0.1371" />
      <parent link="Body_RAR" />
      <child link="rightFoot" />
  </joint>
  <link
    name="Body_RSP">
    <inertial>
      <origin
        xyz="0.0211206130677373 -0.0669651647046125 0.000177534129464537"
        rpy="0 0 0" />
      <mass
        value="0.925752239669232" />
      <inertia
        ixx="0.00168445461161851"
        ixy="-0.0003402060781382"
        ixz="-6.316603382138E-06"
        iyy="0.00157378126324678"
        iyz="7.95927300515075E-06"
        izz="0.00244770101015076" />
    </inertial>
    <visual>
      <origin
        xyz="0 0 0"
        rpy="0 0 0" />
      <geometry>
        <mesh
          filename="package://drchubo-v3/meshes/convhull_RSP_merged.stl" />
      </geometry>
      <material
        name="">
        <color
          rgba="0.752941176470588 0.752941176470588 0.752941176470588 1" />
      </material>
    </visual>
    <collision>
      <origin
        xyz="0 0 0"
        rpy="0 0 0" />
      <geometry>
        <mesh
          filename="package://drchubo-v3/meshes/convhull_RSP_merged.stl" />
      </geometry>
    </collision>
  </link>
  <joint
    name="RSP"
    type="revolute">
    <origin
      xyz="0 -0.1435 0"
      rpy="0 0 0" />
    <parent
      link="Body_Torso" />
    <child
      link="Body_RSP" />
    <axis
      xyz="0 1 0" />
    <limit
      lower="0"
      upper="0"
      effort="0"
      velocity="0" />
  </joint>
  <link
    name="Body_RSR">
    <inertial>
      <origin
        xyz="-0.0375650279692945 0.000356075210703161 -0.0117791110905603"
        rpy="0 0 0" />
      <mass
        value="0.772866145700578" />
      <inertia
        ixx="0.000583426982030745"
        ixy="8.46801592607902E-07"
        ixz="-3.33711094991844E-05"
        iyy="0.000797704704734503"
        iyz="-1.18578919660246E-05"
        izz="0.00056129458605824" />
    </inertial>
    <visual>
      <origin
        xyz="0 0 0"
        rpy="0 0 0" />
      <geometry>
        <mesh
          filename="package://drchubo-v3/meshes/convhull_RSR_merged.stl" />
      </geometry>
      <material
        name="">
        <color
          rgba="0.752941176470588 0.752941176470588 0.752941176470588 1" />
      </material>
    </visual>
    <collision>
      <origin
        xyz="0 0 0"
        rpy="0 0 0" />
      <geometry>
        <mesh
          filename="package://drchubo-v3/meshes/convhull_RSR_merged.stl" />
      </geometry>
    </collision>
  </link>
  <joint
    name="RSR"
    type="revolute">
    <origin
      xyz="0.033 -0.086 0"
      rpy="0 0 0" />
    <parent
      link="Body_RSP" />
    <child
      link="Body_RSR" />
    <axis
      xyz="1 0 0" />
    <limit
      lower="0"
      upper="0"
      effort="0"
      velocity="0" />
  </joint>
  <link
    name="Body_RSY">
    <inertial>
      <origin
        xyz="0.00919437021308769 0.00191434175871116 -0.169537229579129"
        rpy="0 0 0" />
      <mass
        value="2.05731646101945" />
      <inertia
        ixx="0.022308439261109"
        ixy="2.50613568021934E-05"
        ixz="-0.00188493824890792"
        iyy="0.022422403784538"
        iyz="-0.00033219310880628"
        izz="0.00158588979968041" />
    </inertial>
    <visual>
      <origin
        xyz="0 0 0"
        rpy="0 0 0" />
      <geometry>
        <mesh
          filename="package://drchubo-v3/meshes/convhull_RSY_merged.stl" />
      </geometry>
      <material
        name="">
        <color
          rgba="0.752941176470588 0.752941176470588 0.752941176470588 1" />
      </material>
    </visual>
    <collision>
      <origin
        xyz="0 0 0"
        rpy="0 0 0" />
      <geometry>
        <mesh
          filename="package://drchubo-v3/meshes/convhull_RSY_merged.stl" />
      </geometry>
    </collision>
  </link>
  <joint
    name="RSY"
    type="revolute">
    <origin
      xyz="-0.0330 0 -0.0270"
      rpy="0 0 0" />
    <parent
      link="Body_RSR" />
    <child
      link="Body_RSY" />
    <axis
      xyz="0 0 1" />
    <limit
      lower="0"
      upper="0"
      effort="0"
      velocity="0" />
  </joint>
  <link
    name="Body_REP">
    <inertial>
      <origin
        xyz="-0.0244460480200548 0.0182798518231346 -0.0396913386769124"
        rpy="0 0 0" />
      <mass
        value="0.298170328161609" />
      <inertia
        ixx="0.00039436325182108"
        ixy="1.34384975567809E-06"
        ixz="7.5799657457728E-05"
        iyy="0.000374815280261367"
        iyz="-2.18982902477903E-06"
        izz="0.000273941918370785" />
    </inertial>
    <visual>
      <origin
        xyz="0 0 0"
        rpy="0 0 0" />
      <geometry>
        <mesh
          filename="package://drchubo-v3/meshes/convhull_REP_merged.stl" />
      </geometry>
      <material
        name="">
        <color
          rgba="0.752941176470588 0.752941176470588 0.752941176470588 1" />
      </material>
    </visual>
    <collision>
      <origin
        xyz="0 0 0"
        rpy="0 0 0" />
      <geometry>
        <mesh
          filename="package://drchubo-v3/meshes/convhull_REP_merged.stl" />
      </geometry>
    </collision>
  </link>
  <joint
    name="REP"
    type="revolute">
    <origin
      xyz="0.0300 -0.0190 -0.273"
      rpy="0 0 0" />
    <parent
      link="Body_RSY" />
    <child
      link="Body_REP" />
    <axis
      xyz="0 1 0" />
    <limit
      lower="0"
      upper="0"
      effort="0"
      velocity="0" />
  </joint>
  <link
    name="Body_RWY">
    <inertial>
      <origin
        xyz="3.39374071555978E-05 -0.0559979630014064 -0.151262292453488"
        rpy="0 0 0" />
      <mass
        value="1.68933309958433" />
      <inertia
        ixx="0.0176540649275"
        ixy="3.61034488578566E-06"
        ixz="8.37319577754474E-06"
        iyy="0.0150234017716201"
        iyz="0.00516603192565906"
        izz="0.00331146614295589" />
    </inertial>
    <visual>
      <origin
        xyz="0 0 0"
        rpy="0 0 0" />
      <geometry>
        <mesh
          filename="package://drchubo-v3/meshes/convhull_RWY_merged.stl" />
      </geometry>
      <material
        name="">
        <color
          rgba="0.752941176470588 0.752941176470588 0.752941176470588 1" />
      </material>
    </visual>
    <collision>
      <origin
        xyz="0 0 0"
        rpy="0 0 0" />
      <geometry>
        <mesh
          filename="package://drchubo-v3/meshes/convhull_RWY_merged.stl" />
      </geometry>
    </collision>
  </link>
  <joint
    name="RWY"
    type="revolute">
    <origin
      xyz="-0.03 0.019 -0.052"
      rpy="0 0 0" />
    <parent
      link="Body_REP" />
    <child
      link="Body_RWY" />
    <axis
      xyz="0 0 1" />
    <limit
      lower="0"
      upper="0"
      effort="0"
      velocity="0" />
  </joint>
  <link
    name="Body_RWP">
    <inertial>
      <origin
        xyz="-0.0145320131223039 0.0546994779181496 -0.000367800192129009"
        rpy="0 0 0" />
      <mass
        value="0.327632198288514" />
      <inertia
        ixx="0.000346968656318936"
        ixy="-5.89262498623108E-05"
        ixz="4.30826482069059E-06"
        iyy="0.000575629790270392"
        iyz="1.25504736046297E-06"
        izz="0.000744124634836377" />
    </inertial>
    <visual>
      <origin
        xyz="0 0 0"
        rpy="0 0 0" />
      <geometry>
        <mesh
          filename="package://drchubo-v3/meshes/convhull_RWP_merged.stl" />
      </geometry>
      <material
        name="">
        <color
          rgba="0.752941176470588 0.752941176470588 0.752941176470588 1" />
      </material>
    </visual>
    <collision>
      <origin
        xyz="0 0 0"
        rpy="0 0 0" />
      <geometry>
        <mesh
          filename="package://drchubo-v3/meshes/convhull_RWP_merged.stl" />
      </geometry>
    </collision>
  </link>
  <joint
    name="RWP"
    type="revolute">
    <origin
      xyz="0 -0.067 -0.2618"
      rpy="0 1.57079632679 0" />
    <parent
      link="Body_RWY" />
    <child
      link="Body_RWP" />
    <axis
      xyz="0 1 0" />
    <limit
      lower="0"
      upper="0"
      effort="0"
      velocity="0" />
  </joint>
  <link
    name="Body_RWR">
    <inertial>
      <origin
        xyz="0.0461316332401823 0.000476271776752968 0.000802125417300403"
        rpy="0 0 0" />
      <mass
        value="1.26227162553295" />
      <inertia
        ixx="0.00137019038629361"
        ixy="-6.08173568366545E-05"
        ixz="5.84193124811731E-06"
        iyy="0.00133077281235897"
        iyz="1.17164831962772E-05"
        izz="0.00120357514263781" />
    </inertial>
    <visual>
      <origin
        xyz="0 0 0"
        rpy="0 0 0" />
      <geometry>
        <mesh
          filename="package://drchubo-v3/meshes/convhull_RWR_merged.stl" />
      </geometry>
      <material
        name="">
        <color
          rgba="0.752941176470588 0.752941176470588 0.752941176470588 1" />
      </material>
    </visual>
    <collision>
      <origin
        xyz="0 0 0"
        rpy="0 0 0" />
      <geometry>
        <mesh
          filename="package://drchubo-v3/meshes/convhull_RWR_merged.stl" />
      </geometry>
    </collision>
  </link>
  <joint
    name="RWR"
    type="revolute">
    <origin
      xyz="0.027 0.0670 0"
      rpy="0 0 0" />
    <parent
      link="Body_RWP" />
    <child
      link="Body_RWR" />
    <axis
      xyz="1 0 0" />
    <limit
      lower="0"
      upper="0"
      effort="0"
      velocity="0" />
  </joint>
  <link name="rightPalm">
      <inertial>
          <origin rpy="0 0 0" xyz="0 0 0" />
          <mass value=".1" />
          <inertia ixx="0.0001" ixy="0" ixz="0" iyy="0.0001" iyz="0" izz="0.0001" />
      </inertial>
  </link>
    <joint name="RWR_dummy" type="fixed">
        <origin rpy="0 0 -1.57079632679" xyz="0.1 0 0" />
        <parent link="Body_RWR" />
        <child link="rightPalm" />
    </joint>
  <link
    name="Body_NK1">
    <inertial>
      <origin
        xyz="-0.013163 1.7706E-06 0.036774"
        rpy="0 0 0" />
      <mass
        value="0.18123" />
      <inertia
        ixx="0.0001082"
        ixy="8.5747E-10"
        ixz="-2.1626E-06"
        iyy="0.00011192"
        iyz="-1.3008E-09"
        izz="0.00011594" />
    </inertial>
    <visual>
      <origin
        xyz="0 0 0"
        rpy="0 0 0" />
      <geometry>
        <mesh
          filename="package://drchubo-v3/meshes/convhull_NK1_merged.stl" />
      </geometry>
      <material
        name="">
        <color
          rgba="0.75294 0.75294 0.75294 1" />
      </material>
    </visual>
    <collision>
      <origin
        xyz="0 0 0"
        rpy="0 0 0" />
      <geometry>
        <mesh
          filename="package://drchubo-v3/meshes/convhull_NK1_merged.stl" />
      </geometry>
    </collision>
  </link>
  <joint
    name="NK1"
    type="revolute">
    <origin
      xyz="0 -1.0274E-05 0.0585"
      rpy="0 0 0" />
    <parent
      link="Body_Torso" />
    <child
      link="Body_NK1" />
    <axis
      xyz="0 0 1" />
    <limit
      effort="0"
      velocity="0" />
  </joint>
  <link
    name="Body_NK2">
    <inertial>
      <origin
        xyz="-0.00051569 -0.035537 0.11073"
        rpy="0 0 0" />
      <mass
        value="0.67971" />
      <inertia
        ixx="0.0048072"
        ixy="-7.0061E-07"
        ixz="-2.0605E-05"
        iyy="0.0030587"
        iyz="-6.6145E-05"
        izz="0.0019744" />
    </inertial>
    <visual>
      <origin
        xyz="0 0 0"
        rpy="0 0 0" />
      <geometry>
        <mesh
          filename="package://drchubo-v3/meshes/convhull_NK2_merged.stl" />
      </geometry>
      <material
        name="">
        <color
          rgba="0.75294 0.75294 0.75294 1" />
      </material>
    </visual>
    <collision>
      <origin
        xyz="0 0 0"
        rpy="0 0 0" />
      <geometry>
        <mesh
          filename="package://drchubo-v3/meshes/convhull_NK2_merged.stl" />
      </geometry>
    </collision>
  </link>
  <joint
    name="NK2"
    type="revolute">
    <origin
      xyz="0 0.0355 0.025"
      rpy="0 0 0" />
    <parent
      link="Body_NK1" />
    <child
      link="Body_NK2" />
    <axis
      xyz="0 1 0" />
    <limit
      lower="0"
      upper="0"
      effort="0"
      velocity="0" />
  </joint>
  <link
    name="Body_NK3">
    <inertial>
      <origin
        xyz="0.00860436308107296 0.0354999996643836 0.00609890405742305"
        rpy="0 0 0" />
      <mass
        value="0.255818051941108" />
      <inertia
        ixx="0.000150249696711292"
        ixy="-9.04389574403584E-11"
        ixz="-3.69168280443323E-06"
        iyy="0.000195009281184693"
        iyz="-9.27911853694594E-13"
        izz="0.000211950785433309" />
    </inertial>
    <visual>
      <origin
        xyz="0 0 0"
        rpy="0 0 0" />
      <geometry>
        <mesh
          filename="package://drchubo-v3/meshes/convhull_NK3_merged.stl" />
      </geometry>
      <material
        name="">
        <color
          rgba="0.752941176470588 0.752941176470588 0.752941176470588 1" />
      </material>
    </visual>
    <collision>
      <origin
        xyz="0 0 0"
        rpy="0 0 0" />
      <geometry>
        <mesh
          filename="package://drchubo-v3/meshes/convhull_NK3_merged.stl" />
      </geometry>
    </collision>
  </link>
  <joint
    name="NK3"
    type="revolute">
    <origin
      xyz="0 -0.071 0.086"
      rpy="0 0 0" />
    <parent
      link="Body_NK2" />
    <child
      link="Body_NK3" />
    <axis
      xyz="0 1 0" />
    <limit
      lower="0"
      upper="0"
      effort="0"
      velocity="0" />
  </joint>
  <link
    name="Body_RF41">
    <inertial>
      <origin
        xyz="0.0136755315274642 0.000167665941499973 0.000198749354247546"
        rpy="0 0 0" />
      <mass
        value="0.0263710561484852" />
      <inertia
        ixx="1.98396452598938E-06"
        ixy="3.66951887147115E-08"
        ixz="-7.82216984075622E-08"
        iyy="6.90160003553662E-06"
        iyz="-5.52885002718446E-09"
        izz="6.59611728996667E-06" />
    </inertial>
    <visual>
      <origin
        xyz="0 0 0"
        rpy="0 0 0" />
      <geometry>
        <mesh
          filename="package://drchubo-v3/meshes/convhull_RF11.stl" />
      </geometry>
      <material
        name="">
        <color
          rgba="0.752941176470588 0.752941176470588 0.752941176470588 1" />
      </material>
    </visual>
    <collision>
      <origin
        xyz="0 0 0"
        rpy="0 0 0" />
      <geometry>
        <mesh
          filename="package://drchubo-v3/meshes/convhull_RF11.stl" />
      </geometry>
    </collision>
  </link>
  <joint
    name="RF41"
    type="revolute">
    <origin
      xyz="0.0875 0.026 0.0445"
      rpy="-1.5708 1.3605E-15 -1.2503E-31" />
    <parent
        link="Body_RWR" />
    <child
      link="Body_RF41" />
    <axis
      xyz="0 0 -1" />
    <limit
      lower="0"
      upper="0"
      effort="0"
      velocity="0" />
  </joint>
  <link
    name="Body_RF42">
    <inertial>
      <origin
        xyz="0.0110393059886056 0.000234060880174747 5.56986057551612E-05"
        rpy="0 0 0" />
      <mass
        value="0.0161893682490371" />
      <inertia
        ixx="1.30911370817583E-06"
        ixy="1.49423602565039E-08"
        ixz="-5.01486524728835E-08"
        iyy="2.82043860524338E-06"
        iyz="-2.86294445270114E-09"
        izz="3.05888536890684E-06" />
    </inertial>
    <visual>
      <origin
        xyz="0 0 0"
        rpy="0 0 0" />
      <geometry>
        <mesh
          filename="package://drchubo-v3/meshes/convhull_RF12_merged.stl" />
      </geometry>
      <material
        name="">
        <color
          rgba="0.752941176470588 0.752941176470588 0.752941176470588 1" />
      </material>
    </visual>
    <collision>
      <origin
        xyz="0 0 0"
        rpy="0 0 0" />
      <geometry>
        <mesh
          filename="package://drchubo-v3/meshes/convhull_RF12_merged.stl" />
      </geometry>
    </collision>
  </link>
  <joint
    name="RF42"
    type="revolute">
    <origin
      xyz="0.041952 0 -0.002"
      rpy="2.6604E-15 1.3963 2.3539E-15" />
    <parent
      link="Body_RF41" />
    <child
      link="Body_RF42" />
    <axis
      xyz="0 1 0" />
    <limit
      lower="0"
      upper="0"
      effort="0"
      velocity="0" />
    <mimic
        joint="RF41"/>
  </joint>
  <link
    name="Body_RF43">
    <inertial>
      <origin
        xyz="0.0171497739791413 -0.000431859131655776 0.000224831410368165"
        rpy="0 0 0" />
      <mass
        value="0.0182221650876647" />
      <inertia
        ixx="1.0318161748715E-06"
        ixy="-4.94978359878605E-08"
        ixz="-1.22492186703522E-07"
        iyy="2.57254536615945E-06"
        iyz="-5.58418574877856E-09"
        izz="2.54656084717461E-06" />
    </inertial>
    <visual>
      <origin
        xyz="0 0 0"
        rpy="0 0 0" />
      <geometry>
        <mesh
          filename="package://drchubo-v3/meshes/convhull_RF13_merged.stl" />
      </geometry>
      <material
        name="">
        <color
          rgba="0.752941176470588 0.752941176470588 0.752941176470588 1" />
      </material>
    </visual>
    <collision>
      <origin
        xyz="0 0 0"
        rpy="0 0 0" />
      <geometry>
        <mesh
          filename="package://drchubo-v3/meshes/convhull_RF13_merged.stl" />
      </geometry>
    </collision>
  </link>
  <joint
    name="RF43"
    type="revolute">
    <origin
      xyz="0.029967 0 -0.0014"
      rpy="-4.431E-16 1.3963 1.9134E-16" />
    <parent
      link="Body_RF42" />
    <child
      link="Body_RF43" />
    <axis
      xyz="0 1 0" />
    <limit
      lower="0"
      upper="0"
      effort="0"
      velocity="0" />
    <mimic
        joint="RF41"/>
  </joint>
  <link
    name="Body_RF11">
    <inertial>
      <origin
        xyz="0.0136755350449784 0.000167665760227642 0.000198749511991281"
        rpy="0 0 0" />
      <mass
        value="0.0263710648327817" />
      <inertia
        ixx="1.98396439062456E-06"
        ixy="3.66951330319436E-08"
        ixz="-7.8221681308727E-08"
        iyy="6.90160086477887E-06"
        iyz="-5.52885566500941E-09"
        izz="6.59611827284368E-06" />
    </inertial>
    <visual>
      <origin
        xyz="0 0 0"
        rpy="0 0 0" />
      <geometry>
        <mesh
          filename="package://drchubo-v3/meshes/convhull_RF11.stl" />
      </geometry>
      <material
        name="">
        <color
          rgba="0.752941176470588 0.752941176470588 0.752941176470588 1" />
      </material>
    </visual>
    <collision>
      <origin
        xyz="0 0 0"
        rpy="0 0 0" />
      <geometry>
        <mesh
          filename="package://drchubo-v3/meshes/convhull_RF11.stl" />
      </geometry>
    </collision>
  </link>
  <joint
    name="RF11"
    type="revolute">
    <origin
      xyz="0.0875 -0.026 0.02247"
      rpy="1.5708 1.8188E-16 -1.6542E-14" />
    <parent
      link="Body_RWR" />
    <child
      link="Body_RF11" />
    <axis
      xyz="0 0 1" />
    <limit
      lower="0"
      upper="0"
      effort="0"
      velocity="0" />
  </joint>
  <link
    name="Body_RF12">
    <inertial>
      <origin
        xyz="0.0110393059886056 0.000234060880174858 5.56986057552722E-05"
        rpy="0 0 0" />
      <mass
        value="0.0161893682490371" />
      <inertia
        ixx="1.30911370817583E-06"
        ixy="1.49423602564968E-08"
        ixz="-5.01486524728809E-08"
        iyy="2.82043860524338E-06"
        iyz="-2.86294445269988E-09"
        izz="3.05888536890683E-06" />
    </inertial>
    <visual>
      <origin
        xyz="0 0 0"
        rpy="0 0 0" />
      <geometry>
        <mesh
          filename="package://drchubo-v3/meshes/convhull_RF12_merged.stl" />
      </geometry>
      <material
        name="">
        <color
          rgba="0.752941176470588 0.752941176470588 0.752941176470588 1" />
      </material>
    </visual>
    <collision>
      <origin
        xyz="0 0 0"
        rpy="0 0 0" />
      <geometry>
        <mesh
          filename="package://drchubo-v3/meshes/convhull_RF12_merged.stl" />
      </geometry>
    </collision>
  </link>
  <joint
    name="RF12"
    type="revolute">
    <origin
      xyz="0.041952 0 -0.002"
      rpy="-1.9804E-17 1.3963 5.1283E-17" />
    <parent
      link="Body_RF11" />
    <child
      link="Body_RF12" />
    <axis
      xyz="0 1 0" />
    <limit
      lower="0"
      upper="0"
      effort="0"
      velocity="0" />
    <mimic
        joint="RF11"/>
  </joint>
  <link
    name="Body_RF13">
    <inertial>
      <origin
        xyz="0.0171497739791414 -0.000431859131655887 0.000224831410368082"
        rpy="0 0 0" />
      <mass
        value="0.0182221650876645" />
      <inertia
        ixx="1.03181617487149E-06"
        ixy="-4.94978359878614E-08"
        ixz="-1.22492186703508E-07"
        iyy="2.57254536615943E-06"
        iyz="-5.58418574878542E-09"
        izz="2.54656084717459E-06" />
    </inertial>
    <visual>
      <origin
        xyz="0 0 0"
        rpy="0 0 0" />
      <geometry>
        <mesh
          filename="package://drchubo-v3/meshes/convhull_RF13_merged.stl" />
      </geometry>
      <material
        name="">
        <color
          rgba="0.752941176470588 0.752941176470588 0.752941176470588 1" />
      </material>
    </visual>
    <collision>
      <origin
        xyz="0 0 0"
        rpy="0 0 0" />
      <geometry>
        <mesh
          filename="package://drchubo-v3/meshes/convhull_RF13_merged.stl" />
      </geometry>
    </collision>
  </link>
  <joint
    name="RF13"
    type="revolute">
    <origin
      xyz="0.029967 0 -0.0014"
      rpy="3.3698E-16 1.3963 2.1055E-16" />
    <parent
      link="Body_RF12" />
    <child
      link="Body_RF13" />
    <axis
      xyz="0 1 0" />
    <limit
      lower="0"
      upper="0"
      effort="0"
      velocity="0" />
    <mimic
        joint="RF11"/>
  </joint>
  <link
    name="Body_RF21">
    <inertial>
      <origin
        xyz="0.0136755350449784 0.000167665760227642 0.000198749511991309"
        rpy="0 0 0" />
      <mass
        value="0.0263710648327817" />
      <inertia
        ixx="1.98396439062456E-06"
        ixy="3.66951330319451E-08"
        ixz="-7.82216813087296E-08"
        iyy="6.90160086477887E-06"
        iyz="-5.52885566500572E-09"
        izz="6.59611827284368E-06" />
    </inertial>
    <visual>
      <origin
        xyz="0 0 0"
        rpy="0 0 0" />
      <geometry>
        <mesh
          filename="package://drchubo-v3/meshes/convhull_RF11.stl" />
      </geometry>
      <material
        name="">
        <color
          rgba="0.752941176470588 0.752941176470588 0.752941176470588 1" />
      </material>
    </visual>
    <collision>
      <origin
        xyz="0 0 0"
        rpy="0 0 0" />
      <geometry>
        <mesh
          filename="package://drchubo-v3/meshes/convhull_RF11.stl" />
      </geometry>
    </collision>
  </link>
  <joint
    name="RF21"
    type="revolute">
    <origin
      xyz="0.0875 0.026 3E-05"
      rpy="-1.5708 1.6226E-15 -1.6577E-14" />
    <parent
      link="Body_RWR" />
    <child
      link="Body_RF21" />
    <axis
      xyz="0 0 -1" />
    <limit
      lower="0"
      upper="0"
      effort="0"
      velocity="0" />
    <mimic
        joint="RF11"/>
  </joint>
  <link
    name="Body_RF22">
    <inertial>
      <origin
        xyz="0.0110393059886057 0.000234060880174858 5.56986057551889E-05"
        rpy="0 0 0" />
      <mass
        value="0.0161893682490371" />
      <inertia
        ixx="1.30911370817584E-06"
        ixy="1.49423602565011E-08"
        ixz="-5.01486524728848E-08"
        iyy="2.82043860524337E-06"
        iyz="-2.86294445270055E-09"
        izz="3.05888536890684E-06" />
    </inertial>
    <visual>
      <origin
        xyz="0 0 0"
        rpy="0 0 0" />
      <geometry>
        <mesh
          filename="package://drchubo-v3/meshes/convhull_RF12_merged.stl" />
      </geometry>
      <material
        name="">
        <color
          rgba="0.752941176470588 0.752941176470588 0.752941176470588 1" />
      </material>
    </visual>
    <collision>
      <origin
        xyz="0 0 0"
        rpy="0 0 0" />
      <geometry>
        <mesh
          filename="package://drchubo-v3/meshes/convhull_RF12_merged.stl" />
      </geometry>
    </collision>
  </link>
  <joint
    name="RF22"
    type="revolute">
    <origin
      xyz="0.041952 0 -0.002"
      rpy="5.7379E-16 1.3963 1.5704E-15" />
    <parent
      link="Body_RF21" />
    <child
      link="Body_RF22" />
    <axis
      xyz="0 1 0" />
    <limit
      lower="0"
      upper="0"
      effort="0"
      velocity="0" />
    <mimic
        joint="RF11"/>
  </joint>
  <link
    name="Body_RF23">
    <inertial>
      <origin
        xyz="0.0171497739791413 -0.000431859131655776 0.00022483141036822"
        rpy="0 0 0" />
      <mass
        value="0.0182221650876646" />
      <inertia
        ixx="1.0318161748715E-06"
        ixy="-4.94978359878546E-08"
        ixz="-1.22492186703517E-07"
        iyy="2.57254536615944E-06"
        iyz="-5.58418574878065E-09"
        izz="2.5465608471746E-06" />
    </inertial>
    <visual>
      <origin
        xyz="0 0 0"
        rpy="0 0 0" />
      <geometry>
        <mesh
          filename="package://drchubo-v3/meshes/convhull_RF13_merged.stl" />
      </geometry>
      <material
        name="">
        <color
          rgba="0.752941176470588 0.752941176470588 0.752941176470588 1" />
      </material>
    </visual>
    <collision>
      <origin
        xyz="0 0 0"
        rpy="0 0 0" />
      <geometry>
        <mesh
          filename="package://drchubo-v3/meshes/convhull_RF13_merged.stl" />
      </geometry>
    </collision>
  </link>
  <joint
    name="RF23"
    type="revolute">
    <origin
      xyz="0.029967 0 -0.0014"
      rpy="-6.9275E-15 1.3963 -7.4004E-15" />
    <parent
      link="Body_RF22" />
    <child
      link="Body_RF23" />
    <axis
      xyz="0 1 0" />
    <limit
      lower="0"
      upper="0"
      effort="0"
      velocity="0" />
    <mimic
        joint="RF11"/>
  </joint>
  <link
    name="Body_RF31">
    <inertial>
      <origin
        xyz="0.0136755350449782 0.000167665760227531 0.000198749511991281"
        rpy="0 0 0" />
      <mass
        value="0.0263710648327814" />
      <inertia
        ixx="1.98396439062453E-06"
        ixy="3.66951330319293E-08"
        ixz="-7.82216813087199E-08"
        iyy="6.90160086477879E-06"
        iyz="-5.52885566502119E-09"
        izz="6.5961182728436E-06" />
    </inertial>
    <visual>
      <origin
        xyz="0 0 0"
        rpy="0 0 0" />
      <geometry>
        <mesh
          filename="package://drchubo-v3/meshes/convhull_RF11.stl" />
      </geometry>
      <material
        name="">
        <color
          rgba="0.752941176470588 0.752941176470588 0.752941176470588 1" />
      </material>
    </visual>
    <collision>
      <origin
        xyz="0 0 0"
        rpy="0 0 0" />
      <geometry>
        <mesh
          filename="package://drchubo-v3/meshes/convhull_RF11.stl" />
      </geometry>
    </collision>
  </link>
  <joint
    name="RF31"
    type="revolute">
    <origin
      xyz="0.0875 -0.026 -0.02247"
      rpy="1.5708 1.6626E-15 -1.6538E-14" />
    <parent
      link="Body_RWR" />
    <child
      link="Body_RF31" />
    <axis
      xyz="0 0 1" />
    <limit
      lower="0"
      upper="0"
      effort="0"
      velocity="0" />
    <mimic
        joint="RF11"/>
  </joint>
  <link
    name="Body_RF32">
    <inertial>
      <origin
        xyz="0.0110393059886054 0.00023406088017508 5.56986057551612E-05"
        rpy="0 0 0" />
      <mass
        value="0.0161893682490372" />
      <inertia
        ixx="1.30911370817583E-06"
        ixy="1.49423602565035E-08"
        ixz="-5.01486524728804E-08"
        iyy="2.82043860524337E-06"
        iyz="-2.86294445269586E-09"
        izz="3.05888536890683E-06" />
    </inertial>
    <visual>
      <origin
        xyz="0 0 0"
        rpy="0 0 0" />
      <geometry>
        <mesh
          filename="package://drchubo-v3/meshes/convhull_RF12_merged.stl" />
      </geometry>
      <material
        name="">
        <color
          rgba="0.752941176470588 0.752941176470588 0.752941176470588 1" />
      </material>
    </visual>
    <collision>
      <origin
        xyz="0 0 0"
        rpy="0 0 0" />
      <geometry>
        <mesh
          filename="package://drchubo-v3/meshes/convhull_RF12_merged.stl" />
      </geometry>
    </collision>
  </link>
  <joint
    name="RF32"
    type="revolute">
    <origin
      xyz="0.041952 0 -0.002"
      rpy="3.4418E-15 1.3963 1.7616E-15" />
    <parent
      link="Body_RF31" />
    <child
      link="Body_RF32" />
    <axis
      xyz="0 1 0" />
    <limit
      lower="0"
      upper="0"
      effort="0"
      velocity="0" />
    <mimic
        joint="RF11"/>
  </joint>
  <link
    name="Body_RF33">
    <inertial>
      <origin
        xyz="0.0171497739791414 -0.000431859131655887 0.000224831410368109"
        rpy="0 0 0" />
      <mass
        value="0.0182221650876646" />
      <inertia
        ixx="1.0318161748715E-06"
        ixy="-4.94978359878626E-08"
        ixz="-1.2249218670352E-07"
        iyy="2.57254536615943E-06"
        iyz="-5.58418574878609E-09"
        izz="2.5465608471746E-06" />
    </inertial>
    <visual>
      <origin
        xyz="0 0 0"
        rpy="0 0 0" />
      <geometry>
        <mesh
          filename="package://drchubo-v3/meshes/convhull_RF13_merged.stl" />
      </geometry>
      <material
        name="">
        <color
          rgba="0.752941176470588 0.752941176470588 0.752941176470588 1" />
      </material>
    </visual>
    <collision>
      <origin
        xyz="0 0 0"
        rpy="0 0 0" />
      <geometry>
        <mesh
          filename="package://drchubo-v3/meshes/convhull_RF13_merged.stl" />
      </geometry>
    </collision>
  </link>
  <joint
    name="RF33"
    type="revolute">
    <origin
      xyz="0.029967 0 -0.0014"
      rpy="9.7551E-15 1.3963 1.073E-14" />
    <parent
      link="Body_RF32" />
    <child
      link="Body_RF33" />
    <axis
      xyz="0 1 0" />
    <limit
      lower="0"
      upper="0"
      effort="0"
      velocity="0" />
    <mimic
        joint="RF11"/>
  </joint>
</robot>
